NOTE : Works with all available python packages in the module, check using conda list command
For conda env creation we recommend apps/anaconda/3EnvCreation module
Downloading: "https://download.pytorch.org/models/resnext50_32x4d-7cdf4587.pth" to /home/cse/mtech/mcs202448/.cache/torch/checkpoints/resnext50_32x4d-7cdf4587.pth
Traceback (most recent call last):
  File "/home/apps/anaconda3_2018/4.6.9/lib/python3.6/urllib/request.py", line 1318, in do_open
    encode_chunked=req.has_header('Transfer-encoding'))
  File "/home/apps/anaconda3_2018/4.6.9/lib/python3.6/http/client.py", line 1262, in request
    self._send_request(method, url, body, headers, encode_chunked)
  File "/home/apps/anaconda3_2018/4.6.9/lib/python3.6/http/client.py", line 1308, in _send_request
    self.endheaders(body, encode_chunked=encode_chunked)
  File "/home/apps/anaconda3_2018/4.6.9/lib/python3.6/http/client.py", line 1257, in endheaders
    self._send_output(message_body, encode_chunked=encode_chunked)
  File "/home/apps/anaconda3_2018/4.6.9/lib/python3.6/http/client.py", line 1036, in _send_output
    self.send(msg)
  File "/home/apps/anaconda3_2018/4.6.9/lib/python3.6/http/client.py", line 974, in send
    self.connect()
  File "/home/apps/anaconda3_2018/4.6.9/lib/python3.6/http/client.py", line 1415, in connect
    super().connect()
  File "/home/apps/anaconda3_2018/4.6.9/lib/python3.6/http/client.py", line 946, in connect
    (self.host,self.port), self.timeout, self.source_address)
  File "/home/apps/anaconda3_2018/4.6.9/lib/python3.6/socket.py", line 724, in create_connection
    raise err
  File "/home/apps/anaconda3_2018/4.6.9/lib/python3.6/socket.py", line 713, in create_connection
    sock.connect(sa)
OSError: [Errno 101] Network is unreachable

During handling of the above exception, another exception occurred:

Traceback (most recent call last):
  File "exp1.py", line 124, in <module>
    model_conv = torchvision.models.resnext50_32x4d(pretrained=True)
  File "/home/apps/anaconda3_2018/4.6.9/lib/python3.6/site-packages/torchvision/models/resnet.py", line 283, in resnext50_32x4d
    pretrained, progress, **kwargs)
  File "/home/apps/anaconda3_2018/4.6.9/lib/python3.6/site-packages/torchvision/models/resnet.py", line 213, in _resnet
    progress=progress)
  File "/home/apps/anaconda3_2018/4.6.9/lib/python3.6/site-packages/torch/hub.py", line 433, in load_state_dict_from_url
    _download_url_to_file(url, cached_file, hash_prefix, progress=progress)
  File "/home/apps/anaconda3_2018/4.6.9/lib/python3.6/site-packages/torch/hub.py", line 349, in _download_url_to_file
    u = urlopen(url)
  File "/home/apps/anaconda3_2018/4.6.9/lib/python3.6/urllib/request.py", line 223, in urlopen
    return opener.open(url, data, timeout)
  File "/home/apps/anaconda3_2018/4.6.9/lib/python3.6/urllib/request.py", line 526, in open
    response = self._open(req, data)
  File "/home/apps/anaconda3_2018/4.6.9/lib/python3.6/urllib/request.py", line 544, in _open
    '_open', req)
  File "/home/apps/anaconda3_2018/4.6.9/lib/python3.6/urllib/request.py", line 504, in _call_chain
    result = func(*args)
  File "/home/apps/anaconda3_2018/4.6.9/lib/python3.6/urllib/request.py", line 1361, in https_open
    context=self._context, check_hostname=self._check_hostname)
  File "/home/apps/anaconda3_2018/4.6.9/lib/python3.6/urllib/request.py", line 1320, in do_open
    raise URLError(err)
urllib.error.URLError: <urlopen error [Errno 101] Network is unreachable>
